2023-01-17 18:14:20,909 ERROR: Exception on /upload_image [POST] [in /Users/joannachen/Desktop/flask_proj/venv/lib/python3.10/site-packages/flask/app.py:1741]
Traceback (most recent call last):
  File "/Users/joannachen/Desktop/flask_proj/venv/lib/python3.10/site-packages/flask/app.py", line 2525, in wsgi_app
    response = self.full_dispatch_request()
  File "/Users/joannachen/Desktop/flask_proj/venv/lib/python3.10/site-packages/flask/app.py", line 1822, in full_dispatch_request
    rv = self.handle_user_exception(e)
  File "/Users/joannachen/Desktop/flask_proj/venv/lib/python3.10/site-packages/flask/app.py", line 1820, in full_dispatch_request
    rv = self.dispatch_request()
  File "/Users/joannachen/Desktop/flask_proj/venv/lib/python3.10/site-packages/flask/app.py", line 1796, in dispatch_request
    return self.ensure_sync(self.view_functions[rule.endpoint])(**view_args)
  File "/Users/joannachen/Desktop/flask_proj/venv/lib/python3.10/site-packages/flask_login/utils.py", line 290, in decorated_view
    return current_app.ensure_sync(func)(*args, **kwargs)
  File "/Users/joannachen/Desktop/flask_proj/app/routes.py", line 206, in upload_image
    return render_template('user.html', filename=filename)
  File "/Users/joannachen/Desktop/flask_proj/venv/lib/python3.10/site-packages/flask/templating.py", line 147, in render_template
    return _render(app, template, context)
  File "/Users/joannachen/Desktop/flask_proj/venv/lib/python3.10/site-packages/flask/templating.py", line 130, in _render
    rv = template.render(context)
  File "/Users/joannachen/Desktop/flask_proj/venv/lib/python3.10/site-packages/jinja2/environment.py", line 1301, in render
    self.environment.handle_exception()
  File "/Users/joannachen/Desktop/flask_proj/venv/lib/python3.10/site-packages/jinja2/environment.py", line 936, in handle_exception
    raise rewrite_traceback_stack(source=source)
  File "/Users/joannachen/Desktop/flask_proj/app/templates/user.html", line 1, in top-level template code
    {% extends 'base.html' %}
  File "/Users/joannachen/Desktop/flask_proj/app/templates/base.html", line 1, in top-level template code
    {% extends 'bootstrap/base.html' %}
  File "/Users/joannachen/Desktop/flask_proj/venv/lib/python3.10/site-packages/flask_bootstrap/templates/bootstrap/base.html", line 1, in top-level template code
    {% block doc -%}
  File "/Users/joannachen/Desktop/flask_proj/venv/lib/python3.10/site-packages/flask_bootstrap/templates/bootstrap/base.html", line 4, in block 'doc'
    {%- block html %}
  File "/Users/joannachen/Desktop/flask_proj/venv/lib/python3.10/site-packages/flask_bootstrap/templates/bootstrap/base.html", line 20, in block 'html'
    {% block body -%}
  File "/Users/joannachen/Desktop/flask_proj/venv/lib/python3.10/site-packages/flask_bootstrap/templates/bootstrap/base.html", line 23, in block 'body'
    {% block content -%}
  File "/Users/joannachen/Desktop/flask_proj/app/templates/base.html", line 43, in block 'content'
    {% block app_content %}{% endblock %}
  File "/Users/joannachen/Desktop/flask_proj/app/templates/user.html", line 8, in block 'app_content'
    <h1>User: {{ user.username }}</h1>
  File "/Users/joannachen/Desktop/flask_proj/venv/lib/python3.10/site-packages/jinja2/environment.py", line 485, in getattr
    return getattr(obj, attribute)
jinja2.exceptions.UndefinedError: 'user' is undefined
2023-01-17 20:09:55,365 INFO: Microblog startup [in /Users/joannachen/Desktop/flask_proj/app/__init__.py:51]
2023-01-17 20:10:30,851 INFO: Microblog startup [in /Users/joannachen/Desktop/flask_proj/app/__init__.py:51]
2023-01-17 20:10:37,948 INFO: Microblog startup [in /Users/joannachen/Desktop/flask_proj/app/__init__.py:51]
2023-01-17 20:19:33,882 INFO: Microblog startup [in /Users/joannachen/Desktop/flask_proj/app/__init__.py:51]
2023-01-17 20:19:37,444 ERROR: Exception on /user/susan [GET] [in /Users/joannachen/Desktop/flask_proj/venv/lib/python3.10/site-packages/flask/app.py:1741]
Traceback (most recent call last):
  File "/Users/joannachen/Desktop/flask_proj/venv/lib/python3.10/site-packages/flask/app.py", line 2525, in wsgi_app
    response = self.full_dispatch_request()
  File "/Users/joannachen/Desktop/flask_proj/venv/lib/python3.10/site-packages/flask/app.py", line 1822, in full_dispatch_request
    rv = self.handle_user_exception(e)
  File "/Users/joannachen/Desktop/flask_proj/venv/lib/python3.10/site-packages/flask/app.py", line 1820, in full_dispatch_request
    rv = self.dispatch_request()
  File "/Users/joannachen/Desktop/flask_proj/venv/lib/python3.10/site-packages/flask/app.py", line 1796, in dispatch_request
    return self.ensure_sync(self.view_functions[rule.endpoint])(**view_args)
  File "/Users/joannachen/Desktop/flask_proj/venv/lib/python3.10/site-packages/flask_login/utils.py", line 290, in decorated_view
    return current_app.ensure_sync(func)(*args, **kwargs)
  File "/Users/joannachen/Desktop/flask_proj/app/routes.py", line 78, in user
    image_file = url_for('static',filename='profile_pics/'+ current_user.image_file)
TypeError: can only concatenate str (not "NoneType") to str
2023-01-17 20:22:16,440 INFO: Microblog startup [in /Users/joannachen/Desktop/flask_proj/app/__init__.py:51]
2023-01-17 20:22:19,047 ERROR: Exception on /user/susan [GET] [in /Users/joannachen/Desktop/flask_proj/venv/lib/python3.10/site-packages/flask/app.py:1741]
Traceback (most recent call last):
  File "/Users/joannachen/Desktop/flask_proj/venv/lib/python3.10/site-packages/flask/app.py", line 2525, in wsgi_app
    response = self.full_dispatch_request()
  File "/Users/joannachen/Desktop/flask_proj/venv/lib/python3.10/site-packages/flask/app.py", line 1822, in full_dispatch_request
    rv = self.handle_user_exception(e)
  File "/Users/joannachen/Desktop/flask_proj/venv/lib/python3.10/site-packages/flask/app.py", line 1820, in full_dispatch_request
    rv = self.dispatch_request()
  File "/Users/joannachen/Desktop/flask_proj/venv/lib/python3.10/site-packages/flask/app.py", line 1796, in dispatch_request
    return self.ensure_sync(self.view_functions[rule.endpoint])(**view_args)
  File "/Users/joannachen/Desktop/flask_proj/venv/lib/python3.10/site-packages/flask_login/utils.py", line 290, in decorated_view
    return current_app.ensure_sync(func)(*args, **kwargs)
  File "/Users/joannachen/Desktop/flask_proj/app/routes.py", line 78, in user
    image_file = url_for('app/static',filename='profile_pics/'+ current_user.image_file)
TypeError: can only concatenate str (not "NoneType") to str
2023-01-17 20:24:04,241 INFO: Microblog startup [in /Users/joannachen/Desktop/flask_proj/app/__init__.py:51]
2023-01-17 20:24:55,645 ERROR: Exception on /user/jy [GET] [in /Users/joannachen/Desktop/flask_proj/venv/lib/python3.10/site-packages/flask/app.py:1741]
Traceback (most recent call last):
  File "/Users/joannachen/Desktop/flask_proj/venv/lib/python3.10/site-packages/flask/app.py", line 2525, in wsgi_app
    response = self.full_dispatch_request()
  File "/Users/joannachen/Desktop/flask_proj/venv/lib/python3.10/site-packages/flask/app.py", line 1822, in full_dispatch_request
    rv = self.handle_user_exception(e)
  File "/Users/joannachen/Desktop/flask_proj/venv/lib/python3.10/site-packages/flask/app.py", line 1820, in full_dispatch_request
    rv = self.dispatch_request()
  File "/Users/joannachen/Desktop/flask_proj/venv/lib/python3.10/site-packages/flask/app.py", line 1796, in dispatch_request
    return self.ensure_sync(self.view_functions[rule.endpoint])(**view_args)
  File "/Users/joannachen/Desktop/flask_proj/venv/lib/python3.10/site-packages/flask_login/utils.py", line 290, in decorated_view
    return current_app.ensure_sync(func)(*args, **kwargs)
  File "/Users/joannachen/Desktop/flask_proj/app/routes.py", line 78, in user
    image_file = url_for('app/static',filename='profile_pics/' + current_user.image_file)
  File "/Users/joannachen/Desktop/flask_proj/venv/lib/python3.10/site-packages/flask/helpers.py", line 256, in url_for
    return current_app.url_for(
  File "/Users/joannachen/Desktop/flask_proj/venv/lib/python3.10/site-packages/flask/app.py", line 2031, in url_for
    return self.handle_url_build_error(error, endpoint, values)
  File "/Users/joannachen/Desktop/flask_proj/venv/lib/python3.10/site-packages/flask/app.py", line 2020, in url_for
    rv = url_adapter.build(  # type: ignore[union-attr]
  File "/Users/joannachen/Desktop/flask_proj/venv/lib/python3.10/site-packages/werkzeug/routing/map.py", line 917, in build
    raise BuildError(endpoint, values, method, self)
werkzeug.routing.exceptions.BuildError: Could not build url for endpoint 'app/static' with values ['filename']. Did you mean 'static' instead?
2023-01-17 20:26:08,271 INFO: Microblog startup [in /Users/joannachen/Desktop/flask_proj/app/__init__.py:51]
2023-01-17 20:28:00,964 INFO: Microblog startup [in /Users/joannachen/Desktop/flask_proj/app/__init__.py:51]
2023-01-17 20:28:17,945 INFO: Microblog startup [in /Users/joannachen/Desktop/flask_proj/app/__init__.py:51]
2023-01-17 20:28:40,080 INFO: Microblog startup [in /Users/joannachen/Desktop/flask_proj/app/__init__.py:51]
2023-01-17 20:49:53,917 INFO: Microblog startup [in /Users/joannachen/Desktop/flask_proj/app/__init__.py:51]
